2017-05-12 18:21:37:
Traceback (most recent call last):
  File "/home/oliver/toutiao_workspace/toutiaohaoWorking/writer_fetch.py", line 270, in fetchContent
    json_dict = json.loads(res_json.content.decode('utf-8'))
  File "/usr/lib/python3.5/json/__init__.py", line 319, in loads
    return _default_decoder.decode(s)
  File "/usr/lib/python3.5/json/decoder.py", line 339, in decode
    obj, end = self.raw_decode(s, idx=_w(s, 0).end())
  File "/usr/lib/python3.5/json/decoder.py", line 357, in raw_decode
    raise JSONDecodeError("Expecting value", s, err.value) from None
json.decoder.JSONDecodeError: Expecting value: line 1 column 1 (char 0)
------------------------------------------

2017-05-12 18:26:41:
Traceback (most recent call last):
  File "/home/oliver/toutiao_workspace/toutiaohaoWorking/writer_fetch.py", line 270, in fetchContent
    json_dict = json.loads(res_json.content.decode('utf-8'))
  File "/usr/lib/python3.5/json/__init__.py", line 319, in loads
    return _default_decoder.decode(s)
  File "/usr/lib/python3.5/json/decoder.py", line 339, in decode
    obj, end = self.raw_decode(s, idx=_w(s, 0).end())
  File "/usr/lib/python3.5/json/decoder.py", line 357, in raw_decode
    raise JSONDecodeError("Expecting value", s, err.value) from None
json.decoder.JSONDecodeError: Expecting value: line 1 column 1 (char 0)
------------------------------------------

2017-05-12 21:34:41:
Traceback (most recent call last):
  File "/home/oliver/toutiao_workspace/toutiaohaoWorking/writer_fetch.py", line 270, in fetchContent
    json_dict = json.loads(res_json.content.decode('utf-8'))
  File "/usr/lib/python3.5/json/__init__.py", line 319, in loads
    return _default_decoder.decode(s)
  File "/usr/lib/python3.5/json/decoder.py", line 339, in decode
    obj, end = self.raw_decode(s, idx=_w(s, 0).end())
  File "/usr/lib/python3.5/json/decoder.py", line 357, in raw_decode
    raise JSONDecodeError("Expecting value", s, err.value) from None
json.decoder.JSONDecodeError: Expecting value: line 1 column 1 (char 0)
------------------------------------------

2017-05-12 21:42:36:
Traceback (most recent call last):
  File "/home/oliver/toutiao_workspace/toutiaohaoWorking/writer_fetch.py", line 270, in fetchContent
    json_dict = json.loads(res_json.content.decode('utf-8'))
  File "/usr/lib/python3.5/json/__init__.py", line 319, in loads
    return _default_decoder.decode(s)
  File "/usr/lib/python3.5/json/decoder.py", line 339, in decode
    obj, end = self.raw_decode(s, idx=_w(s, 0).end())
  File "/usr/lib/python3.5/json/decoder.py", line 357, in raw_decode
    raise JSONDecodeError("Expecting value", s, err.value) from None
json.decoder.JSONDecodeError: Expecting value: line 1 column 1 (char 0)
------------------------------------------

2017-05-15 14:52:02:
Traceback (most recent call last):
  File "/home/oliver/toutiao_workspace/toutiaohaoWorking/writer_fetch.py", line 270, in fetchContent
    json_dict = json.loads(res_json.content.decode('utf-8'))
  File "/usr/lib/python3.5/json/__init__.py", line 319, in loads
    return _default_decoder.decode(s)
  File "/usr/lib/python3.5/json/decoder.py", line 339, in decode
    obj, end = self.raw_decode(s, idx=_w(s, 0).end())
  File "/usr/lib/python3.5/json/decoder.py", line 357, in raw_decode
    raise JSONDecodeError("Expecting value", s, err.value) from None
json.decoder.JSONDecodeError: Expecting value: line 1 column 1 (char 0)
------------------------------------------

2017-05-15 20:45:24:
Traceback (most recent call last):
  File "/home/oliver/toutiao_workspace/toutiaohaoWorking/writer_fetch.py", line 270, in fetchContent
    json_dict = json.loads(res_json.content.decode('utf-8'))
  File "/usr/lib/python3.5/json/__init__.py", line 319, in loads
    return _default_decoder.decode(s)
  File "/usr/lib/python3.5/json/decoder.py", line 339, in decode
    obj, end = self.raw_decode(s, idx=_w(s, 0).end())
  File "/usr/lib/python3.5/json/decoder.py", line 357, in raw_decode
    raise JSONDecodeError("Expecting value", s, err.value) from None
json.decoder.JSONDecodeError: Expecting value: line 1 column 1 (char 0)
------------------------------------------

2017-05-15 21:17:21:
Traceback (most recent call last):
  File "/home/oliver/toutiao_workspace/toutiaohaoWorking/writer_fetch.py", line 270, in fetchContent
    json_dict = json.loads(res_json.content.decode('utf-8'))
  File "/usr/lib/python3.5/json/__init__.py", line 319, in loads
    return _default_decoder.decode(s)
  File "/usr/lib/python3.5/json/decoder.py", line 339, in decode
    obj, end = self.raw_decode(s, idx=_w(s, 0).end())
  File "/usr/lib/python3.5/json/decoder.py", line 357, in raw_decode
    raise JSONDecodeError("Expecting value", s, err.value) from None
json.decoder.JSONDecodeError: Expecting value: line 1 column 1 (char 0)
------------------------------------------

2017-05-16 16:43:50:
Traceback (most recent call last):
  File "/usr/local/lib/python3.5/dist-packages/redis/connection.py", line 439, in connect
    sock = self._connect()
  File "/usr/local/lib/python3.5/dist-packages/redis/connection.py", line 494, in _connect
    raise err
  File "/usr/local/lib/python3.5/dist-packages/redis/connection.py", line 482, in _connect
    sock.connect(socket_address)
ConnectionRefusedError: [Errno 111] Connection refused

During handling of the above exception, another exception occurred:

Traceback (most recent call last):
  File "/usr/local/lib/python3.5/dist-packages/redis/client.py", line 572, in execute_command
    connection.send_command(*args)
  File "/usr/local/lib/python3.5/dist-packages/redis/connection.py", line 563, in send_command
    self.send_packed_command(self.pack_command(*args))
  File "/usr/local/lib/python3.5/dist-packages/redis/connection.py", line 538, in send_packed_command
    self.connect()
  File "/usr/local/lib/python3.5/dist-packages/redis/connection.py", line 442, in connect
    raise ConnectionError(self._error_message(e))
redis.exceptions.ConnectionError: Error 111 connecting to 101.201.37.28:6379. Connection refused.

During handling of the above exception, another exception occurred:

Traceback (most recent call last):
  File "/usr/local/lib/python3.5/dist-packages/redis/connection.py", line 439, in connect
    sock = self._connect()
  File "/usr/local/lib/python3.5/dist-packages/redis/connection.py", line 494, in _connect
    raise err
  File "/usr/local/lib/python3.5/dist-packages/redis/connection.py", line 482, in _connect
    sock.connect(socket_address)
ConnectionRefusedError: [Errno 111] Connection refused

During handling of the above exception, another exception occurred:

Traceback (most recent call last):
  File "/home/oliver/toutiao_workspace/toutiaohaoWorking/writer_fetch.py", line 281, in fetchContent
    is_again_working=json_analyze(uid,datas, articles, gallerys, videos,pool)
  File "/home/oliver/toutiao_workspace/toutiaohaoWorking/writer_fetch.py", line 150, in json_analyze
    is_again_working=check_time(behot_time,pool,uid)
  File "/home/oliver/toutiao_workspace/toutiaohaoWorking/writer_fetch.py", line 87, in check_time
    if rcli.hexists('item_AG_hash',uid):
  File "/usr/local/lib/python3.5/dist-packages/redis/client.py", line 1853, in hexists
    return self.execute_command('HEXISTS', name, key)
  File "/usr/local/lib/python3.5/dist-packages/redis/client.py", line 578, in execute_command
    connection.send_command(*args)
  File "/usr/local/lib/python3.5/dist-packages/redis/connection.py", line 563, in send_command
    self.send_packed_command(self.pack_command(*args))
  File "/usr/local/lib/python3.5/dist-packages/redis/connection.py", line 538, in send_packed_command
    self.connect()
  File "/usr/local/lib/python3.5/dist-packages/redis/connection.py", line 442, in connect
    raise ConnectionError(self._error_message(e))
redis.exceptions.ConnectionError: Error 111 connecting to 101.201.37.28:6379. Connection refused.
------------------------------------------

2017-05-16 17:40:36:
Traceback (most recent call last):
  File "/usr/local/lib/python3.5/dist-packages/requests/packages/urllib3/connectionpool.py", line 600, in urlopen
    chunked=chunked)
  File "/usr/local/lib/python3.5/dist-packages/requests/packages/urllib3/connectionpool.py", line 386, in _make_request
    six.raise_from(e, None)
  File "<string>", line 2, in raise_from
  File "/usr/local/lib/python3.5/dist-packages/requests/packages/urllib3/connectionpool.py", line 382, in _make_request
    httplib_response = conn.getresponse()
  File "/usr/lib/python3.5/http/client.py", line 1198, in getresponse
    response.begin()
  File "/usr/lib/python3.5/http/client.py", line 297, in begin
    version, status, reason = self._read_status()
  File "/usr/lib/python3.5/http/client.py", line 266, in _read_status
    raise RemoteDisconnected("Remote end closed connection without"
http.client.RemoteDisconnected: Remote end closed connection without response

During handling of the above exception, another exception occurred:

Traceback (most recent call last):
  File "/usr/local/lib/python3.5/dist-packages/requests/adapters.py", line 423, in send
    timeout=timeout
  File "/usr/local/lib/python3.5/dist-packages/requests/packages/urllib3/connectionpool.py", line 649, in urlopen
    _stacktrace=sys.exc_info()[2])
  File "/usr/local/lib/python3.5/dist-packages/requests/packages/urllib3/util/retry.py", line 347, in increment
    raise six.reraise(type(error), error, _stacktrace)
  File "/usr/local/lib/python3.5/dist-packages/requests/packages/urllib3/packages/six.py", line 685, in reraise
    raise value.with_traceback(tb)
  File "/usr/local/lib/python3.5/dist-packages/requests/packages/urllib3/connectionpool.py", line 600, in urlopen
    chunked=chunked)
  File "/usr/local/lib/python3.5/dist-packages/requests/packages/urllib3/connectionpool.py", line 386, in _make_request
    six.raise_from(e, None)
  File "<string>", line 2, in raise_from
  File "/usr/local/lib/python3.5/dist-packages/requests/packages/urllib3/connectionpool.py", line 382, in _make_request
    httplib_response = conn.getresponse()
  File "/usr/lib/python3.5/http/client.py", line 1198, in getresponse
    response.begin()
  File "/usr/lib/python3.5/http/client.py", line 297, in begin
    version, status, reason = self._read_status()
  File "/usr/lib/python3.5/http/client.py", line 266, in _read_status
    raise RemoteDisconnected("Remote end closed connection without"
requests.packages.urllib3.exceptions.ProtocolError: ('Connection aborted.', RemoteDisconnected('Remote end closed connection without response',))

During handling of the above exception, another exception occurred:

Traceback (most recent call last):
  File "/home/oliver/toutiao_workspace/toutiaohaoWorking/writer_fetch.py", line 281, in fetchContent
    is_again_working=json_analyze(uid,datas, articles, gallerys, videos,pool)
  File "/home/oliver/toutiao_workspace/toutiaohaoWorking/writer_fetch.py", line 158, in json_analyze
    res = requests.get(url, timeout=30)
  File "/usr/local/lib/python3.5/dist-packages/requests/api.py", line 70, in get
    return request('get', url, params=params, **kwargs)
  File "/usr/local/lib/python3.5/dist-packages/requests/api.py", line 56, in request
    return session.request(method=method, url=url, **kwargs)
  File "/usr/local/lib/python3.5/dist-packages/requests/sessions.py", line 488, in request
    resp = self.send(prep, **send_kwargs)
  File "/usr/local/lib/python3.5/dist-packages/requests/sessions.py", line 609, in send
    r = adapter.send(request, **kwargs)
  File "/usr/local/lib/python3.5/dist-packages/requests/adapters.py", line 473, in send
    raise ConnectionError(err, request=request)
requests.exceptions.ConnectionError: ('Connection aborted.', RemoteDisconnected('Remote end closed connection without response',))
------------------------------------------

2017-12-11 14:22:22:
Traceback (most recent call last):
  File "C:\SharedSpace\toutiaohao\writer_fetch.py", line 316, in fetchContent
    is_again_working=json_analyze(uid,datas, articles, gallerys, videos,others,pool)
  File "C:\SharedSpace\toutiaohao\writer_fetch.py", line 175, in json_analyze
    _dict=json.loads(res.content.decode('utf-8'))
  File "C:\MyUtils\Python35\lib\json\__init__.py", line 319, in loads
    return _default_decoder.decode(s)
  File "C:\MyUtils\Python35\lib\json\decoder.py", line 339, in decode
    obj, end = self.raw_decode(s, idx=_w(s, 0).end())
  File "C:\MyUtils\Python35\lib\json\decoder.py", line 357, in raw_decode
    raise JSONDecodeError("Expecting value", s, err.value) from None
json.decoder.JSONDecodeError: Expecting value: line 1 column 1 (char 0)
------------------------------------------

2017-12-11 17:13:30:
Traceback (most recent call last):
  File "C:\SharedSpace\toutiaohao\writer_fetch.py", line 322, in fetchContent
    is_again_working=json_analyze(uid,datas, articles, gallerys, videos,others,pool)
  File "C:\SharedSpace\toutiaohao\writer_fetch.py", line 211, in json_analyze
    _dict=json_po(res.content.decode('utf-8'))
  File "C:\SharedSpace\toutiaohao\writer_fetch.py", line 152, in json_po
    return json.loads(sa_e)
  File "C:\MyUtils\Python35\lib\json\__init__.py", line 319, in loads
    return _default_decoder.decode(s)
  File "C:\MyUtils\Python35\lib\json\decoder.py", line 339, in decode
    obj, end = self.raw_decode(s, idx=_w(s, 0).end())
  File "C:\MyUtils\Python35\lib\json\decoder.py", line 357, in raw_decode
    raise JSONDecodeError("Expecting value", s, err.value) from None
json.decoder.JSONDecodeError: Expecting value: line 1 column 1 (char 0)
------------------------------------------

2017-12-11 17:16:30:
Traceback (most recent call last):
  File "C:\SharedSpace\toutiaohao\writer_fetch.py", line 324, in fetchContent
    is_again_working=json_analyze(uid,datas, articles, gallerys, videos,others,pool)
  File "C:\SharedSpace\toutiaohao\writer_fetch.py", line 241, in json_analyze
    _dict=json_po(res.content.decode('utf-8'))
  File "C:\SharedSpace\toutiaohao\writer_fetch.py", line 152, in json_po
    return json.loads(sa_e)
  File "C:\MyUtils\Python35\lib\json\__init__.py", line 319, in loads
    return _default_decoder.decode(s)
  File "C:\MyUtils\Python35\lib\json\decoder.py", line 339, in decode
    obj, end = self.raw_decode(s, idx=_w(s, 0).end())
  File "C:\MyUtils\Python35\lib\json\decoder.py", line 357, in raw_decode
    raise JSONDecodeError("Expecting value", s, err.value) from None
json.decoder.JSONDecodeError: Expecting value: line 1 column 1 (char 0)
------------------------------------------

2017-12-11 17:23:31:
Traceback (most recent call last):
  File "C:\SharedSpace\toutiaohao\writer_fetch.py", line 324, in fetchContent
    is_again_working=json_analyze(uid,datas, articles, gallerys, videos,others,pool)
  File "C:\SharedSpace\toutiaohao\writer_fetch.py", line 182, in json_analyze
    _dict=json.loads(res.content.decode('utf-8'))
  File "C:\MyUtils\Python35\lib\json\__init__.py", line 319, in loads
    return _default_decoder.decode(s)
  File "C:\MyUtils\Python35\lib\json\decoder.py", line 339, in decode
    obj, end = self.raw_decode(s, idx=_w(s, 0).end())
  File "C:\MyUtils\Python35\lib\json\decoder.py", line 357, in raw_decode
    raise JSONDecodeError("Expecting value", s, err.value) from None
json.decoder.JSONDecodeError: Expecting value: line 1 column 1 (char 0)
------------------------------------------

2017-12-12 10:36:44:
Traceback (most recent call last):
  File "C:\SharedSpace\toutiaohao\writer_fetch.py", line 337, in fetchContent
    is_again_working=json_analyze(uid,datas, articles, gallerys, videos,others,pool,user_agent)
  File "C:\SharedSpace\toutiaohao\writer_fetch.py", line 254, in json_analyze
    _dict=json_po(res.read())
  File "C:\SharedSpace\toutiaohao\writer_fetch.py", line 150, in json_po
    sa=_str.split(', ')
TypeError: a bytes-like object is required, not 'str'
------------------------------------------

2017-12-12 12:57:18:
Traceback (most recent call last):
  File "C:\SharedSpace\toutiaohao\writer_fetch.py", line 338, in fetchContent
    is_again_working=json_analyze(uid,datas, articles, gallerys, videos,others,pool,user_agent)
  File "C:\SharedSpace\toutiaohao\writer_fetch.py", line 184, in json_analyze
    _dict=json.loads(res.content.decode('utf-8'))
  File "C:\MyUtils\Python35\lib\json\__init__.py", line 319, in loads
    return _default_decoder.decode(s)
  File "C:\MyUtils\Python35\lib\json\decoder.py", line 339, in decode
    obj, end = self.raw_decode(s, idx=_w(s, 0).end())
  File "C:\MyUtils\Python35\lib\json\decoder.py", line 357, in raw_decode
    raise JSONDecodeError("Expecting value", s, err.value) from None
json.decoder.JSONDecodeError: Expecting value: line 1 column 1 (char 0)
------------------------------------------

